Workbook

Sheet Summary
A1: ="DAILY TARGET & LY SUMMARY – "&TEXT($C$4,"ddd dd mmm yyyy")&" vs "&TEXT($F$4,"ddd dd mmm yyyy") -> DAILY TARGET & LY SUMMARY – Thu 01 Oct 2026 vs Mon 26 Oct 2026
A2: ="Target achieved = Sales ≥ "&TEXT($L$4,"0%")&" of daily target | Beat LY = like-for-like stores (LY sales > 0) with TY ≥ "&TEXT($O$4,"0%")&" of same date LY ("&TEXT(EDATE($C$4,-12),"dd mmm yyyy")&")" -> Target achieved = Sales ≥ 80% of daily target | Beat LY = like-for-like stores (LY sales > 0) with TY ≥ 100% of same date LY (01 Oct 2025)
A4: Report Date ▼ | C4: 46296 | E4: Compare Date ▼ | F4: 46321 | H4: ="Latest date with sales loaded: "&TEXT('Sales Dashboard'!$AZ$6,"dd mmm yyyy") -> Latest date with sales loaded: 26 Oct 2026 | K4: Target achieved if Ach % ≥ | L4: 0.8 | N4: LFL beat LY if TY/LY ≥ | O4: 1
AB5: STORE CALC (helper) – AB:AL report date, AM:AS compare date | AU5: DATE LIST (dropdown source)
A6: HEADLINE | B6: =TEXT($C$4,"dd mmm") -> 01 Oct | C6: ="Names – "&TEXT($C$4,"dd mmm") -> Names – 01 Oct | Q6: =TEXT($F$4,"dd mmm") -> 26 Oct | R6: ="Names – "&TEXT($F$4,"dd mmm") -> Names – 26 Oct | AB6: Store | AC6: Area Manager | AD6: City | AE6: Sales TY (day) | AF6: Daily Target | AG6: LY Sales (same date) | AH6: Has Target | AI6: Achieved Target | AJ6: LFL | AK6: Beat LY | AL6: Valid AM | AM6: Sales (Compare) | AN6: Target (Compare) | AO6: LY Sales (Compare) | AP6: Has Target (Compare) | AQ6: Achieved (Compare) | AR6: LFL (Compare) | AS6: Beat LY (Compare) | AU6: {=_xlfn._xlws.FILTER(_xlfn.ANCHORARRAY('Sales Dashboard'!$AY$6),_xlfn.ANCHORARRAY('Sales Dashboard'!$AY$6)<='Sales Dashboard'!$AZ$6)} -> 46296
A7: ="Area Managers achieved target (≥"&TEXT($L$4,"0%")&")" -> Area Managers achieved target (≥80%) | B7: =F26 -> 0 of 8 | C7: {=_xlfn.TEXTJOIN(", ",TRUE,_xlfn._xlws.FILTER(A16:A25,F16:F25="✔ Yes","None"))} -> None | Q7: =U26 -> 0 of 8 | R7: {=_xlfn.TEXTJOIN(", ",TRUE,_xlfn._xlws.FILTER(A16:A25,U16:U25="✔ Yes","None"))} -> None | AB7: =IF('Sales Dashboard'!AW5="","",'Sales Dashboard'!AW5) -> HAOTHASS | AC7: =IF(AB7="","",'Sales Dashboard'!AN5) -> Hamzah Al Makhadam | AD7: =IF(AB7="","",'Sales Dashboard'!AO5) -> Al Hasa | AE7: {=IF(OR(AB7="",NOT(ISNUMBER('Sales Dashboard'!BF5))),0,SUMPRODUCT((IFERROR(--'Sales and count'!$G$2:$CC$2,0)=$C$4)*('Sales and count'!$G$3:$CC$3="Total"),INDEX('Sales and count'!$G$4:$CC$300,'Sales Dashboard'!BF5,0)))} -> 11939.14 | AF7: {=IF(OR(AB7="",NOT(ISNUMBER('Sales Dashboard'!BG5))),0,SUMPRODUCT(('TY Sales Target'!$K$2:$AO$2=$C$4)*1,INDEX('TY Sales Target'!$K$5:$AO$300,'Sales Dashboard'!BG5,0)))} -> 10689.192 | AG7: {=IF(AB7="",0,SUMPRODUCT((TRIM('LY Sales '!$B$5:$B$200)=AB7)*('LY Sales '!$C$2:$AG$2=EDATE($C$4,-12)),'LY Sales '!$C$5:$AG$200))} -> 10503.31 | AH7: =--AND(AB7<>"",AF7>0) -> 1 | AI7: =--AND(AH7=1,AE7>=AF7*$L$4) -> 1 | AJ7: =--AND(AB7<>"",AG7>0) -> 1 | AK7: =--AND(AJ7=1,AE7>=AG7*$O$4) -> 1 | AL7: =--AND(AC7<>"",AC7<>"No assignment",AC7<>"Unassigned") -> 1 | AM7: {=IF(OR(AB7="",NOT(ISNUMBER('Sales Dashboard'!BF5))),0,SUMPRODUCT((IFERROR(--'Sales and count'!$G$2:$CC$2,0)=$F$4)*('Sales and count'!$G$3:$CC$3="Total"),INDEX('Sales and count'!$G$4:$CC$300,'Sales Dashboard'!BF5,0)))} -> 4633.23 | AN7: {=IF(OR(AB7="",NOT(ISNUMBER('Sales Dashboard'!BG5))),0,SUMPRODUCT(('TY Sales Target'!$K$2:$AO$2=$F$4)*1,INDEX('TY Sales Target'!$K$5:$AO$300,'Sales Dashboard'!BG5,0)))} -> 7421.638 | AO7: {=IF(AB7="",0,SUMPRODUCT((TRIM('LY Sales '!$B$5:$B$200)=AB7)*('LY Sales '!$C$2:$AG$2=EDATE($F$4,-12)),'LY Sales '!$C$5:$AG$200))} -> 5587.08 | AP7: =--AND(AB7<>"",AN7>0) -> 1 | AQ7: =--AND(AP7=1,AM7>=AN7*$L$4) -> 0 | AR7: =--AND(AB7<>"",AO7>0) -> 1 | AS7: =--AND(AR7=1,AM7>=AO7*$O$4) -> 0 | AU7: 46297
A8: ="Area Managers beat LY (LFL ≥"&TEXT($O$4,"0%")&")" -> Area Managers beat LY (LFL ≥100%) | B8: =N26 -> 0 of 8 | C8: {=_xlfn.TEXTJOIN(", ",TRUE,_xlfn._xlws.FILTER(A16:A25,N16:N25="✔ Yes","None"))} -> None | Q8: =COUNTIF(W16:W25,">="&($O$4-1))&" of "&COUNT(W16:W25) -> 0 of 8 | R8: {=_xlfn.TEXTJOIN(", ",TRUE,_xlfn._xlws.FILTER(A16:A25,IF(ISNUMBER(W16:W25),W16:W25>=$O$4-1,FALSE),"None"))} -> None | AB8: =IF('Sales Dashboard'!AW7="","",'Sales Dashboard'!AW7) -> HAPALMJED | AC8: =IF(AB8="","",'Sales Dashboard'!AN7) -> Ahlam Al Zahrani | AD8: =IF(AB8="","",'Sales Dashboard'!AO7) -> Jeddah | AE8: {=IF(OR(AB8="",NOT(ISNUMBER('Sales Dashboard'!BF7))),0,SUMPRODUCT((IFERROR(--'Sales and count'!$G$2:$CC$2,0)=$C$4)*('Sales and count'!$G$3:$CC$3="Total"),INDEX('Sales and count'!$G$4:$CC$300,'Sales Dashboard'!BF7,0)))} -> 10718.22 | AF8: {=IF(OR(AB8="",NOT(ISNUMBER('Sales Dashboard'!BG7))),0,SUMPRODUCT(('TY Sales Target'!$K$2:$AO$2=$C$4)*1,INDEX('TY Sales Target'!$K$5:$AO$300,'Sales Dashboard'!BG7,0)))} -> 10131.936 | AG8: {=IF(AB8="",0,SUMPRODUCT((TRIM('LY Sales '!$B$5:$B$200)=AB8)*('LY Sales '!$C$2:$AG$2=EDATE($C$4,-12)),'LY Sales '!$C$5:$AG$200))} -> 0 | AH8: =--AND(AB8<>"",AF8>0) -> 1 | AI8: =--AND(AH8=1,AE8>=AF8*$L$4) -> 1 | AJ8: =--AND(AB8<>"",AG8>0) -> 0 | AK8: =--AND(AJ8=1,AE8>=AG8*$O$4) -> 0 | AL8: =--AND(AC8<>"",AC8<>"No assignment",AC8<>"Unassigned") -> 1 | AM8: {=IF(OR(AB8="",NOT(ISNUMBER('Sales Dashboard'!BF7))),0,SUMPRODUCT((IFERROR(--'Sales and count'!$G$2:$CC$2,0)=$F$4)*('Sales and count'!$G$3:$CC$3="Total"),INDEX('Sales and count'!$G$4:$CC$300,'Sales Dashboard'!BF7,0)))} -> 4492.35 | AN8: {=IF(OR(AB8="",NOT(ISNUMBER('Sales Dashboard'!BG7))),0,SUMPRODUCT(('TY Sales Target'!$K$2:$AO$2=$F$4)*1,INDEX('TY Sales Target'!$K$5:$AO$300,'Sales Dashboard'!BG7,0)))} -> 7034.728 | AO8: {=IF(AB8="",0,SUMPRODUCT((TRIM('LY Sales '!$B$5:$B$200)=AB8)*('LY Sales '!$C$2:$AG$2=EDATE($F$4,-12)),'LY Sales '!$C$5:$AG$200))} -> 0 | AP8: =--AND(AB8<>"",AN8>0) -> 1 | AQ8: =--AND(AP8=1,AM8>=AN8*$L$4) -> 0 | AR8: =--AND(AB8<>"",AO8>0) -> 0 | AS8: =--AND(AR8=1,AM8>=AO8*$O$4) -> 0 | AU8: 46298
A9: ="Cities achieved target (≥"&TEXT($L$4,"0%")&")" -> Cities achieved target (≥80%) | B9: =F70 -> 5 of 31 | C9: {=_xlfn.TEXTJOIN(", ",TRUE,_xlfn._xlws.FILTER(A30:A69,F30:F69="✔ Yes","None"))} -> Al Hasa, Dawadami, Jizan, Qurayat, Yanbu | Q9: =U70 -> 0 of 31 | R9: {=_xlfn.TEXTJOIN(", ",TRUE,_xlfn._xlws.FILTER(A30:A69,U30:U69="✔ Yes","None"))} -> None | AB9: =IF('Sales Dashboard'!AW8="","",'Sales Dashboard'!AW8) -> TAHLIAST | AC9: =IF(AB9="","",'Sales Dashboard'!AN8) -> Ahlam Al Zahrani | AD9: =IF(AB9="","",'Sales Dashboard'!AO8) -> Jeddah | AE9: {=IF(OR(AB9="",NOT(ISNUMBER('Sales Dashboard'!BF8))),0,SUMPRODUCT((IFERROR(--'Sales and count'!$G$2:$CC$2,0)=$C$4)*('Sales and count'!$G$3:$CC$3="Total"),INDEX('Sales and count'!$G$4:$CC$300,'Sales Dashboard'!BF8,0)))} -> 8917.23 | AF9: {=IF(OR(AB9="",NOT(ISNUMBER('Sales Dashboard'!BG8))),0,SUMPRODUCT(('TY Sales Target'!$K$2:$AO$2=$C$4)*1,INDEX('TY Sales Target'!$K$5:$AO$300,'Sales Dashboard'!BG8,0)))} -> 12411.621 | AG9: {=IF(AB9="",0,SUMPRODUCT((TRIM('LY Sales '!$B$5:$B$200)=AB9)*('LY Sales '!$C$2:$AG$2=EDATE($C$4,-12)),'LY Sales '!$C$5:$AG$200))} -> 16722.58 | AH9: =--AND(AB9<>"",AF9>0) -> 1 | AI9: =--AND(AH9=1,AE9>=AF9*$L$4) -> 0 | AJ9: =--AND(AB9<>"",AG9>0) -> 1 | AK9: =--AND(AJ9=1,AE9>=AG9*$O$4) -> 0 | AL9: =--AND(AC9<>"",AC9<>"No assignment",AC9<>"Unassigned") -> 1 | AM9: {=IF(OR(AB9="",NOT(ISNUMBER('Sales Dashboard'!BF8))),0,SUMPRODUCT((IFERROR(--'Sales and count'!$G$2:$CC$2,0)=$F$4)*('Sales and count'!$G$3:$CC$3="Total"),INDEX('Sales and count'!$G$4:$CC$300,'Sales Dashboard'!BF8,0)))} -> 3522.2 | AN9: {=IF(OR(AB9="",NOT(ISNUMBER('Sales Dashboard'!BG8))),0,SUMPRODUCT(('TY Sales Target'!$K$2:$AO$2=$F$4)*1,INDEX('TY Sales Target'!$K$5:$AO$300,'Sales Dashboard'!BG8,0)))} -> 8617.5418 | AO9: {=IF(AB9="",0,SUMPRODUCT((TRIM('LY Sales '!$B$5:$B$200)=AB9)*('LY Sales '!$C$2:$AG$2=EDATE($F$4,-12)),'LY Sales '!$C$5:$AG$200))} -> 7356.16 | AP9: =--AND(AB9<>"",AN9>0) -> 1 | AQ9: =--AND(AP9=1,AM9>=AN9*$L$4) -> 0 | AR9: =--AND(AB9<>"",AO9>0) -> 1 | AS9: =--AND(AR9=1,AM9>=AO9*$O$4) -> 0 | AU9: 46299
A10: ="Cities beat LY (LFL ≥"&TEXT($O$4,"0%")&")" -> Cities beat LY (LFL ≥100%) | B10: =N70 -> 4 of 20 | C10: {=_xlfn.TEXTJOIN(", ",TRUE,_xlfn._xlws.FILTER(A30:A69,N30:N69="✔ Yes","None"))} -> Buraidah, Jubail, Khobar, Qatif | Q10: =COUNTIF(W30:W69,">="&($O$4-1))&" of "&COUNT(W30:W69) -> 5 of 23 | R10: {=_xlfn.TEXTJOIN(", ",TRUE,_xlfn._xlws.FILTER(A30:A69,IF(ISNUMBER(W30:W69),W30:W69>=$O$4-1,FALSE),"None"))} -> Buraidah, Dammam, Madinah, Qatif, Sabya | AB10: =IF('Sales Dashboard'!AW9="","",'Sales Dashboard'!AW9) -> HAMYANYARD | AC10: =IF(AB10="","",'Sales Dashboard'!AN9) -> Maram Zamzami | AD10: =IF(AB10="","",'Sales Dashboard'!AO9) -> Makkah | AE10: {=IF(OR(AB10="",NOT(ISNUMBER('Sales Dashboard'!BF9))),0,SUMPRODUCT((IFERROR(--'Sales and count'!$G$2:$CC$2,0)=$C$4)*('Sales and count'!$G$3:$CC$3="Total"),INDEX('Sales and count'!$G$4:$CC$300,'Sales Dashboard'!BF9,0)))} -> 8811.14 | AF10: {=IF(OR(AB10="",NOT(ISNUMBER('Sales Dashboard'!BG9))),0,SUMPRODUCT(('TY Sales Target'!$K$2:$AO$2=$C$4)*1,INDEX('TY Sales Target'!$K$5:$AO$300,'Sales Dashboard'!BG9,0)))} -> 8612.1455 | AG10: {=IF(AB10="",0,SUMPRODUCT((TRIM('LY Sales '!$B$5:$B$200)=AB10)*('LY Sales '!$C$2:$AG$2=EDATE($C$4,-12)),'LY Sales '!$C$5:$AG$200))} -> 10913.25 | AH10: =--AND(AB10<>"",AF10>0) -> 1 | AI10: =--AND(AH10=1,AE10>=AF10*$L$4) -> 1 | AJ10: =--AND(AB10<>"",AG10>0) -> 1 | AK10: =--AND(AJ10=1,AE10>=AG10*$O$4) -> 0 | AL10: =--AND(AC10<>"",AC10<>"No assignment",AC10<>"Unassigned") -> 1 | AM10: {=IF(OR(AB10="",NOT(ISNUMBER('Sales Dashboard'!BF9))),0,SUMPRODUCT((IFERROR(--'Sales and count'!$G$2:$CC$2,0)=$F$4)*('Sales and count'!$G$3:$CC$3="Total"),INDEX('Sales and count'!$G$4:$CC$300,'Sales Dashboard'!BF9,0)))} -> 3406.22 | AN10: {=IF(OR(AB10="",NOT(ISNUMBER('Sales Dashboard'!BG9))),0,SUMPRODUCT(('TY Sales Target'!$K$2:$AO$2=$F$4)*1,INDEX('TY Sales Target'!$K$5:$AO$300,'Sales Dashboard'!BG9,0)))} -> 5979.5188 | AO10: {=IF(AB10="",0,SUMPRODUCT((TRIM('LY Sales '!$B$5:$B$200)=AB10)*('LY Sales '!$C$2:$AG$2=EDATE($F$4,-12)),'LY Sales '!$C$5:$AG$200))} -> 2306.04 | AP10: =--AND(AB10<>"",AN10>0) -> 1 | AQ10: =--AND(AP10=1,AM10>=AN10*$L$4) -> 0 | AR10: =--AND(AB10<>"",AO10>0) -> 1 | AS10: =--AND(AR10=1,AM10>=AO10*$O$4) -> 1 | AU10: 46300
A11: ="Stores achieved target (≥"&TEXT($L$4,"0%")&")" -> Stores achieved target (≥80%) | B11: =SUM($AI$7:$AI$303)&" of "&SUM($AH$7:$AH$303) -> 20 of 115 | Q11: =SUM($AQ$7:$AQ$303)&" of "&SUM($AP$7:$AP$303) -> 6 of 115 | AB11: =IF('Sales Dashboard'!AW10="","",'Sales Dashboard'!AW10) -> HAMAKANMAL | AC11: =IF(AB11="","",'Sales Dashboard'!AN10) -> Lina Al Ghathami | AD11: =IF(AB11="","",'Sales Dashboard'!AO10) -> Dawadami | AE11: {=IF(OR(AB11="",NOT(ISNUMBER('Sales Dashboard'!BF10))),0,SUMPRODUCT((IFERROR(--'Sales and count'!$G$2:$CC$2,0)=$C$4)*('Sales and count'!$G$3:$CC$3="Total"),INDEX('Sales and count'!$G$4:$CC$300,'Sales Dashboard'!BF10,0)))} -> 4209.13 | AF11: {=IF(OR(AB11="",NOT(ISNUMBER('Sales Dashboard'!BG10))),0,SUMPRODUCT(('TY Sales Target'!$K$2:$AO$2=$C$4)*1,INDEX('TY Sales Target'!$K$5:$AO$300,'Sales Dashboard'!BG10,0)))} -> 4812.6695 | AG11: {=IF(AB11="",0,SUMPRODUCT((TRIM('LY Sales '!$B$5:$B$200)=AB11)*('LY Sales '!$C$2:$AG$2=EDATE($C$4,-12)),'LY Sales '!$C$5:$AG$200))} -> 0 | AH11: =--AND(AB11<>"",AF11>0) -> 1 | AI11: =--AND(AH11=1,AE11>=AF11*$L$4) -> 1 | AJ11: =--AND(AB11<>"",AG11>0) -> 0 | AK11: =--AND(AJ11=1,AE11>=AG11*$O$4) -> 0 | AL11: =--AND(AC11<>"",AC11<>"No assignment",AC11<>"Unassigned") -> 1 | AM11: {=IF(OR(AB11="",NOT(ISNUMBER('Sales Dashboard'!BF10))),0,SUMPRODUCT((IFERROR(--'Sales and count'!$G$2:$CC$2,0)=$F$4)*('Sales and count'!$G$3:$CC$3="Total"),INDEX('Sales and count'!$G$4:$CC$300,'Sales Dashboard'!BF10,0)))} -> 2656.15 | AN11: {=IF(OR(AB11="",NOT(ISNUMBER('Sales Dashboard'!BG10))),0,SUMPRODUCT(('TY Sales Target'!$K$2:$AO$2=$F$4)*1,INDEX('TY Sales Target'!$K$5:$AO$300,'Sales Dashboard'!BG10,0)))} -> 3341.4958 | AO11: {=IF(AB11="",0,SUMPRODUCT((TRIM('LY Sales '!$B$5:$B$200)=AB11)*('LY Sales '!$C$2:$AG$2=EDATE($F$4,-12)),'LY Sales '!$C$5:$AG$200))} -> 0 | AP11: =--AND(AB11<>"",AN11>0) -> 1 | AQ11: =--AND(AP11=1,AM11>=AN11*$L$4) -> 0 | AR11: =--AND(AB11<>"",AO11>0) -> 0 | AS11: =--AND(AR11=1,AM11>=AO11*$O$4) -> 0 | AU11: 46301
A12: ="LFL stores beat LY (≥"&TEXT($O$4,"0%")&")" -> LFL stores beat LY (≥100%) | B12: =SUM($AK$7:$AK$303)&" of "&SUM($AJ$7:$AJ$303) -> 15 of 59 | Q12: =SUM($AS$7:$AS$303)&" of "&SUM($AR$7:$AR$303) -> 21 of 64 | AB12: =IF('Sales Dashboard'!AW11="","",'Sales Dashboard'!AW11) -> HAABRAJ1 | AC12: =IF(AB12="","",'Sales Dashboard'!AN11) -> Maram Zamzami | AD12: =IF(AB12="","",'Sales Dashboard'!AO11) -> Makkah | AE12: {=IF(OR(AB12="",NOT(ISNUMBER('Sales Dashboard'!BF11))),0,SUMPRODUCT((IFERROR(--'Sales and count'!$G$2:$CC$2,0)=$C$4)*('Sales and count'!$G$3:$CC$3="Total"),INDEX('Sales and count'!$G$4:$CC$300,'Sales Dashboard'!BF11,0)))} -> 26466.61 | AF12: {=IF(OR(AB12="",NOT(ISNUMBER('Sales Dashboard'!BG11))),0,SUMPRODUCT(('TY Sales Target'!$K$2:$AO$2=$C$4)*1,INDEX('TY Sales Target'!$K$5:$AO$300,'Sales Dashboard'!BG11,0)))} -> 37994.759 | AG12: {=IF(AB12="",0,SUMPRODUCT((TRIM('LY Sales '!$B$5:$B$200)=AB12)*('LY Sales '!$C$2:$AG$2=EDATE($C$4,-12)),'LY Sales '!$C$5:$AG$200))} -> 0 | AH12: =--AND(AB12<>"",AF12>0) -> 1 | AI12: =--AND(AH12=1,AE12>=AF12*$L$4) -> 0 | AJ12: =--AND(AB12<>"",AG12>0) -> 0 | AK12: =--AND(AJ12=1,AE12>=AG12*$O$4) -> 0 | AL12: =--AND(AC12<>"",AC12<>"No assignment",AC12<>"Unassigned") -> 1 | AM12: {=IF(OR(AB12="",NOT(ISNUMBER('Sales Dashboard'!BF11))),0,SUMPRODUCT((IFERROR(--'Sales and count'!$G$2:$CC$2,0)=$F$4)*('Sales and count'!$G$3:$CC$3="Total"),INDEX('Sales and count'!$G$4:$CC$300,'Sales Dashboard'!BF11,0)))} -> 12409.9 | AN12: {=IF(OR(AB12="",NOT(ISNUMBER('Sales Dashboard'!BG11))),0,SUMPRODUCT(('TY Sales Target'!$K$2:$AO$2=$F$4)*1,INDEX('TY Sales Target'!$K$5:$AO$300,'Sales Dashboard'!BG11,0)))} -> 26380.23 | AO12: {=IF(AB12="",0,SUMPRODUCT((TRIM('LY Sales '!$B$5:$B$200)=AB12)*('LY Sales '!$C$2:$AG$2=EDATE($F$4,-12)),'LY Sales '!$C$5:$AG$200))} -> 0 | AP12: =--AND(AB12<>"",AN12>0) -> 1 | AQ12: =--AND(AP12=1,AM12>=AN12*$L$4) -> 0 | AR12: =--AND(AB12<>"",AO12>0) -> 0 | AS12: =--AND(AR12=1,AM12>=AO12*$O$4) -> 0 | AU12: 46302
AB13: =IF('Sales Dashboard'!AW12="","",'Sales Dashboard'!AW12) -> HADANAYAN | AC13: =IF(AB13="","",'Sales Dashboard'!AN12) -> Mohammed Haidar | AD13: =IF(AB13="","",'Sales Dashboard'!AO12) -> Yanbu | AE13: {=IF(OR(AB13="",NOT(ISNUMBER('Sales Dashboard'!BF12))),0,SUMPRODUCT((IFERROR(--'Sales and count'!$G$2:$CC$2,0)=$C$4)*('Sales and count'!$G$3:$CC$3="Total"),INDEX('Sales and count'!$G$4:$CC$300,'Sales Dashboard'!BF12,0)))} -> 4773.07 | AF13: {=IF(OR(AB13="",NOT(ISNUMBER('Sales Dashboard'!BG12))),0,SUMPRODUCT(('TY Sales Target'!$K$2:$AO$2=$C$4)*1,INDEX('TY Sales Target'!$K$5:$AO$300,'Sales Dashboard'!BG12,0)))} -> 5420.5857 | AG13: {=IF(AB13="",0,SUMPRODUCT((TRIM('LY Sales '!$B$5:$B$200)=AB13)*('LY Sales '!$C$2:$AG$2=EDATE($C$4,-12)),'LY Sales '!$C$5:$AG$200))} -> 0 | AH13: =--AND(AB13<>"",AF13>0) -> 1 | AI13: =--AND(AH13=1,AE13>=AF13*$L$4) -> 1 | AJ13: =--AND(AB13<>"",AG13>0) -> 0 | AK13: =--AND(AJ13=1,AE13>=AG13*$O$4) -> 0 | AL13: =--AND(AC13<>"",AC13<>"No assignment",AC13<>"Unassigned") -> 1 | AM13: {=IF(OR(AB13="",NOT(ISNUMBER('Sales Dashboard'!BF12))),0,SUMPRODUCT((IFERROR(--'Sales and count'!$G$2:$CC$2,0)=$F$4)*('Sales and count'!$G$3:$CC$3="Total"),INDEX('Sales and count'!$G$4:$CC$300,'Sales Dashboard'!BF12,0)))} -> 1660.11 | AN13: {=IF(OR(AB13="",NOT(ISNUMBER('Sales Dashboard'!BG12))),0,SUMPRODUCT(('TY Sales Target'!$K$2:$AO$2=$F$4)*1,INDEX('TY Sales Target'!$K$5:$AO$300,'Sales Dashboard'!BG12,0)))} -> 3763.5795 | AO13: {=IF(AB13="",0,SUMPRODUCT((TRIM('LY Sales '!$B$5:$B$200)=AB13)*('LY Sales '!$C$2:$AG$2=EDATE($F$4,-12)),'LY Sales '!$C$5:$AG$200))} -> 0 | AP13: =--AND(AB13<>"",AN13>0) -> 1 | AQ13: =--AND(AP13=1,AM13>=AN13*$L$4) -> 0 | AR13: =--AND(AB13<>"",AO13>0) -> 0 | AS13: =--AND(AR13=1,AM13>=AO13*$O$4) -> 0 | AU13: 46303
A14: BY AREA MANAGER | E14: ="REPORT DATE: "&TEXT($C$4,"ddd dd mmm yyyy") -> REPORT DATE: Thu 01 Oct 2026 | Q14: ="COMPARE DATE: "&TEXT($F$4,"ddd dd mmm yyyy") -> COMPARE DATE: Mon 26 Oct 2026 | AB14: =IF('Sales Dashboard'!AW13="","",'Sales Dashboard'!AW13) -> HADARTAW2 | AC14: =IF(AB14="","",'Sales Dashboard'!AN13) -> Maram Zamzami | AD14: =IF(AB14="","",'Sales Dashboard'!AO13) -> Makkah | AE14: {=IF(OR(AB14="",NOT(ISNUMBER('Sales Dashboard'!BF13))),0,SUMPRODUCT((IFERROR(--'Sales and count'!$G$2:$CC$2,0)=$C$4)*('Sales and count'!$G$3:$CC$3="Total"),INDEX('Sales and count'!$G$4:$CC$300,'Sales Dashboard'!BF13,0)))} -> 28795.78 | AF14: {=IF(OR(AB14="",NOT(ISNUMBER('Sales Dashboard'!BG13))),0,SUMPRODUCT(('TY Sales Target'!$K$2:$AO$2=$C$4)*1,INDEX('TY Sales Target'!$K$5:$AO$300,'Sales Dashboard'!BG13,0)))} -> 47113.502 | AG14: {=IF(AB14="",0,SUMPRODUCT((TRIM('LY Sales '!$B$5:$B$200)=AB14)*('LY Sales '!$C$2:$AG$2=EDATE($C$4,-12)),'LY Sales '!$C$5:$AG$200))} -> 0 | AH14: =--AND(AB14<>"",AF14>0) -> 1 | AI14: =--AND(AH14=1,AE14>=AF14*$L$4) -> 0 | AJ14: =--AND(AB14<>"",AG14>0) -> 0 | AK14: =--AND(AJ14=1,AE14>=AG14*$O$4) -> 0 | AL14: =--AND(AC14<>"",AC14<>"No assignment",AC14<>"Unassigned") -> 1 | AM14: {=IF(OR(AB14="",NOT(ISNUMBER('Sales Dashboard'!BF13))),0,SUMPRODUCT((IFERROR(--'Sales and count'!$G$2:$CC$2,0)=$F$4)*('Sales and count'!$G$3:$CC$3="Total"),INDEX('Sales and count'!$G$4:$CC$300,'Sales Dashboard'!BF13,0)))} -> 19781.05 | AN14: {=IF(OR(AB14="",NOT(ISNUMBER('Sales Dashboard'!BG13))),0,SUMPRODUCT(('TY Sales Target'!$K$2:$AO$2=$F$4)*1,INDEX('TY Sales Target'!$K$5:$AO$300,'Sales Dashboard'!BG13,0)))} -> 32711.485 | AO14: {=IF(AB14="",0,SUMPRODUCT((TRIM('LY Sales '!$B$5:$B$200)=AB14)*('LY Sales '!$C$2:$AG$2=EDATE($F$4,-12)),'LY Sales '!$C$5:$AG$200))} -> 0 | AP14: =--AND(AB14<>"",AN14>0) -> 1 | AQ14: =--AND(AP14=1,AM14>=AN14*$L$4) -> 0 | AR14: =--AND(AB14<>"",AO14>0) -> 0 | AS14: =--AND(AR14=1,AM14>=AO14*$O$4) -> 0 | AU14: 46304
A15: Area Manager | B15: Stores | C15: ="Sales "&TEXT($C$4,"dd mmm") -> Sales 01 Oct | D15: ="Target "&TEXT($C$4,"dd mmm") -> Target 01 Oct | E15: Ach % vs Target | F15: ="Achieved Target? (≥"&TEXT($L$4,"0%")&")" -> Achieved Target? (≥80%) | G15: Stores with Target | H15: Stores Achieved | I15: Stores Achieved (x of y) | J15: LFL Stores | K15: LFL Sales TY | L15: LFL Sales LY | M15: LFL Growth % | N15: ="Beat LY? (≥"&TEXT($O$4,"0%")&")" -> Beat LY? (≥100%) | O15: LFL Stores Beat LY | P15: Stores Beat LY (x of y) | Q15: ="Sales "&TEXT($F$4,"dd mmm") -> Sales 26 Oct | R15: ="Sales Change % vs "&TEXT($F$4,"dd mmm") -> Sales Change % vs 26 Oct | S15: ="Ach % "&TEXT($F$4,"dd mmm") -> Ach % 26 Oct | T15: ="Ach % Change (pts)" -> Ach % Change (pts) | U15: ="Achieved Target? "&TEXT($F$4,"dd mmm") -> Achieved Target? 26 Oct | V15: ="Stores Achieved "&TEXT($F$4,"dd mmm") -> Stores Achieved 26 Oct | W15: ="LFL Growth % "&TEXT($F$4,"dd mmm") -> LFL Growth % 26 Oct | X15: ="Stores Beat LY "&TEXT($F$4,"dd mmm") -> Stores Beat LY 26 Oct | AB15: =IF('Sales Dashboard'!AW14="","",'Sales Dashboard'!AW14) -> HAWAHABLVD | AC15: =IF(AB15="","",'Sales Dashboard'!AN14) -> Ahlam Al Zahrani | AD15: =IF(AB15="","",'Sales Dashboard'!AO14) -> Jeddah | AE15: {=IF(OR(AB15="",NOT(ISNUMBER('Sales Dashboard'!BF14))),0,SUMPRODUCT((IFERROR(--'Sales and count'!$G$2:$CC$2,0)=$C$4)*('Sales and count'!$G$3:$CC$3="Total"),INDEX('Sales and count'!$G$4:$CC$300,'Sales Dashboard'!BF14,0)))} -> 6723.06 | AF15: {=IF(OR(AB15="",NOT(ISNUMBER('Sales Dashboard'!BG14))),0,SUMPRODUCT(('TY Sales Target'!$K$2:$AO$2=$C$4)*1,INDEX('TY Sales Target'!$K$5:$AO$300,'Sales Dashboard'!BG14,0)))} -> 8358.8471 | AG15: {=IF(AB15="",0,SUMPRODUCT((TRIM('LY Sales '!$B$5:$B$200)=AB15)*('LY Sales '!$C$2:$AG$2=EDATE($C$4,-12)),'LY Sales '!$C$5:$AG$200))} -> 0 | AH15: =--AND(AB15<>"",AF15>0) -> 1 | AI15: =--AND(AH15=1,AE15>=AF15*$L$4) -> 1 | AJ15: =--AND(AB15<>"",AG15>0) -> 0 | AK15: =--AND(AJ15=1,AE15>=AG15*$O$4) -> 0 | AL15: =--AND(AC15<>"",AC15<>"No assignment",AC15<>"Unassigned") -> 1 | AM15: {=IF(OR(AB15="",NOT(ISNUMBER('Sales Dashboard'!BF14))),0,SUMPRODUCT((IFERROR(--'Sales and count'!$G$2:$CC$2,0)=$F$4)*('Sales and count'!$G$3:$CC$3="Total"),INDEX('Sales and count'!$G$4:$CC$300,'Sales Dashboard'!BF14,0)))} -> 2738.16 | AN15: {=IF(OR(AB15="",NOT(ISNUMBER('Sales Dashboard'!BG14))),0,SUMPRODUCT(('TY Sales Target'!$K$2:$AO$2=$F$4)*1,INDEX('TY Sales Target'!$K$5:$AO$300,'Sales Dashboard'!BG14,0)))} -> 5803.6506 | AO15: {=IF(AB15="",0,SUMPRODUCT((TRIM('LY Sales '!$B$5:$B$200)=AB15)*('LY Sales '!$C$2:$AG$2=EDATE($F$4,-12)),'LY Sales '!$C$5:$AG$200))} -> 0 | AP15: =--AND(AB15<>"",AN15>0) -> 1 | AQ15: =--AND(AP15=1,AM15>=AN15*$L$4) -> 0 | AR15: =--AND(AB15<>"",AO15>0) -> 0 | AS15: =--AND(AR15=1,AM15>=AO15*$O$4) -> 0 | AU15: 46305
A16: {=IFERROR(INDEX(_xlfn._xlws.SORT(_xlfn.UNIQUE(_xlfn._xlws.FILTER($AC$7:$AC$303,$AL$7:$AL$303=1))),ROWS($A$16:A16)),"")} -> Ahlam Al Zahrani | B16: =IF($A16="","",COUNTIFS($AC$7:$AC$303,$A16,$AL$7:$AL$303,1)) -> 13 | C16: =IF($A16="","",SUMIFS($AE$7:$AE$303,$AC$7:$AC$303,$A16,$AL$7:$AL$303,1)) -> 113474.39 | D16: =IF($A16="","",SUMIFS($AF$7:$AF$303,$AC$7:$AC$303,$A16,$AL$7:$AL$303,1)) -> 163060.73 | E16: =IF(OR($A16="",N(D16)=0),"",C16/D16) -> 0.69590264 | F16: =IF(OR($A16="",N(D16)=0),"",IF(C16>=D16*$L$4,"✔ Yes","✘ No")) -> ✘ No | G16: =IF($A16="","",COUNTIFS($AC$7:$AC$303,$A16,$AH$7:$AH$303,1,$AL$7:$AL$303,1)) -> 13 | H16: =IF($A16="","",COUNTIFS($AC$7:$AC$303,$A16,$AI$7:$AI$303,1,$AL$7:$AL$303,1)) -> 4 | I16: =IF($A16="","",H16&" of "&G16) -> 4 of 13 | J16: =IF($A16="","",COUNTIFS($AC$7:$AC$303,$A16,$AJ$7:$AJ$303,1,$AL$7:$AL$303,1)) -> 6 | K16: =IF($A16="","",SUMIFS($AE$7:$AE$303,$AC$7:$AC$303,$A16,$AJ$7:$AJ$303,1,$AL$7:$AL$303,1)) -> 57631.38 | L16: =IF($A16="","",SUMIFS($AG$7:$AG$303,$AC$7:$AC$303,$A16,$AJ$7:$AJ$303,1,$AL$7:$AL$303,1)) -> 66750.99 | M16: =IF(OR($A16="",N(L16)=0),"",K16/L16-1) -> -0.13662134 | N16: =IF(OR($A16="",N(L16)=0),"",IF(K16>=L16*$O$4,"✔ Yes","✘ No")) -> ✘ No | O16: =IF($A16="","",COUNTIFS($AC$7:$AC$303,$A16,$AK$7:$AK$303,1,$AL$7:$AL$303,1)) -> 2 | P16: =IF($A16="","",O16&" of "&J16) -> 2 of 6 | Q16: =IF($A16="","",SUMIFS($AM$7:$AM$303,$AC$7:$AC$303,$A16,$AL$7:$AL$303,1)) -> 49959.12 | R16: =IF(OR($A16="",N(Q16)=0),"",C16/Q16-1) -> 1.2713449 | S16: =IF($A16="","",IFERROR(Q16/SUMIFS($AN$7:$AN$303,$AC$7:$AC$303,$A16,$AL$7:$AL$303,1),"")) -> 0.44127623 | T16: =IF(OR(E16="",S16=""),"",(E16-S16)*100) -> 25.462642 | U16: =IF(S16="","",IF(S16>=$L$4,"✔ Yes","✘ No")) -> ✘ No | V16: =IF($A16="","",COUNTIFS($AC$7:$AC$303,$A16,$AQ$7:$AQ$303,1,$AL$7:$AL$303,1)&" of "&COUNTIFS($AC$7:$AC$303,$A16,$AP$7:$AP$303,1,$AL$7:$AL$303,1)) -> 0 of 13 | W16: =IF($A16="","",IFERROR(SUMIFS($AM$7:$AM$303,$AC$7:$AC$303,$A16,$AR$7:$AR$303,1,$AL$7:$AL$303,1)/SUMIFS($AO$7:$AO$303,$AC$7:$AC$303,$A16,$AR$7:$AR$303,1,$AL$7:$AL$303,1)-1,"")) -> -0.10997225 | X16: =IF($A16="","",COUNTIFS($AC$7:$AC$303,$A16,$AS$7:$AS$303,1,$AL$7:$AL$303,1)&" of "&COUNTIFS($AC$7:$AC$303,$A16,$AR$7:$AR$303,1,$AL$7:$AL$303,1)) -> 3 of 6 | AB16: =IF('Sales Dashboard'!AW15="","",'Sales Dashboard'!AW15) -> YANBUMALL | AC16: =IF(AB16="","",'Sales Dashboard'!AN15) -> Mohammed Haidar | AD16: =IF(AB16="","",'Sales Dashboard'!AO15) -> Yanbu | AE16: {=IF(OR(AB16="",NOT(ISNUMBER('Sales Dashboard'!BF15))),0,SUMPRODUCT((IFERROR(--'Sales and count'!$G$2:$CC$2,0)=$C$4)*('Sales and count'!$G$3:$CC$3="Total"),INDEX('Sales and count'!$G$4:$CC$300,'Sales Dashboard'!BF15,0)))} -> 5937.07 | AF16: {=IF(OR(AB16="",NOT(ISNUMBER('Sales Dashboard'!BG15))),0,SUMPRODUCT(('TY Sales Target'!$K$2:$AO$2=$C$4)*1,INDEX('TY Sales Target'!$K$5:$AO$300,'Sales Dashboard'!BG15,0)))} -> 7446.9728 | AG16: {=IF(AB16="",0,SUMPRODUCT((TRIM('LY Sales '!$B$5:$B$200)=AB16)*('LY Sales '!$C$2:$AG$2=EDATE($C$4,-12)),'LY Sales '!$C$5:$AG$200))} -> 10677.2 | AH16: =--AND(AB16<>"",AF16>0) -> 1 | AI16: =--AND(AH16=1,AE16>=AF16*$L$4) -> 0 | AJ16: =--AND(AB16<>"",AG16>0) -> 1 | AK16: =--AND(AJ16=1,AE16>=AG16*$O$4) -> 0 | AL16: =--AND(AC16<>"",AC16<>"No assignment",AC16<>"Unassigned") -> 1 | AM16: {=IF(OR(AB16="",NOT(ISNUMBER('Sales Dashboard'!BF15))),0,SUMPRODUCT((IFERROR(--'Sales and count'!$G$2:$CC$2,0)=$F$4)*('Sales and count'!$G$3:$CC$3="Total"),INDEX('Sales and count'!$G$4:$CC$300,'Sales Dashboard'!BF15,0)))} -> 2753.18 | AN16: {=IF(OR(AB16="",NOT(ISNUMBER('Sales Dashboard'!BG15))),0,SUMPRODUCT(('TY Sales Target'!$K$2:$AO$2=$F$4)*1,INDEX('TY Sales Target'!$K$5:$AO$300,'Sales Dashboard'!BG15,0)))} -> 5170.5251 | AO16: {=IF(AB16="",0,SUMPRODUCT((TRIM('LY Sales '!$B$5:$B$200)=AB16)*('LY Sales '!$C$2:$AG$2=EDATE($F$4,-12)),'LY Sales '!$C$5:$AG$200))} -> 9586.24 | AP16: =--AND(AB16<>"",AN16>0) -> 1 | AQ16: =--AND(AP16=1,AM16>=AN16*$L$4) -> 0 | AR16: =--AND(AB16<>"",AO16>0) -> 1 | AS16: =--AND(AR16=1,AM16>=AO16*$O$4) -> 0 | AU16: 46306
A17: {=IFERROR(INDEX(_xlfn._xlws.SORT(_xlfn.UNIQUE(_xlfn._xlws.FILTER($AC$7:$AC$303,$AL$7:$AL$303=1))),ROWS($A$16:A17)),"")} -> Ahmed Jaffari | B17: =IF($A17="","",COUNTIFS($AC$7:$AC$303,$A17,$AL$7:$AL$303,1)) -> 15 | C17: =IF($A17="","",SUMIFS($AE$7:$AE$303,$AC$7:$AC$303,$A17,$AL$7:$AL$303,1)) -> 121908.92 | D17: =IF($A17="","",SUMIFS($AF$7:$AF$303,$AC$7:$AC$303,$A17,$AL$7:$AL$303,1)) -> 190986.99 | E17: =IF(OR($A17="",N(D17)=0),"",C17/D17) -> 0.63831007 | F17: =IF(OR($A17="",N(D17)=0),"",IF(C17>=D17*$L$4,"✔ Yes","✘ No")) -> ✘ No | G17: =IF($A17="","",COUNTIFS($AC$7:$AC$303,$A17,$AH$7:$AH$303,1,$AL$7:$AL$303,1)) -> 15 | H17: =IF($A17="","",COUNTIFS($AC$7:$AC$303,$A17,$AI$7:$AI$303,1,$AL$7:$AL$303,1)) -> 2 | I17: =IF($A17="","",H17&" of "&G17) -> 2 of 15 | J17: =IF($A17="","",COUNTIFS($AC$7:$AC$303,$A17,$AJ$7:$AJ$303,1,$AL$7:$AL$303,1)) -> 7 | K17: =IF($A17="","",SUMIFS($AE$7:$AE$303,$AC$7:$AC$303,$A17,$AJ$7:$AJ$303,1,$AL$7:$AL$303,1)) -> 73202.77 | L17: =IF($A17="","",SUMIFS($AG$7:$AG$303,$AC$7:$AC$303,$A17,$AJ$7:$AJ$303,1,$AL$7:$AL$303,1)) -> 114982.21 | M17: =IF(OR($A17="",N(L17)=0),"",K17/L17-1) -> -0.36335569 | N17: =IF(OR($A17="",N(L17)=0),"",IF(K17>=L17*$O$4,"✔ Yes","✘ No")) -> ✘ No | O17: =IF($A17="","",COUNTIFS($AC$7:$AC$303,$A17,$AK$7:$AK$303,1,$AL$7:$AL$303,1)) -> 1 | P17: =IF($A17="","",O17&" of "&J17) -> 1 of 7 | Q17: =IF($A17="","",SUMIFS($AM$7:$AM$303,$AC$7:$AC$303,$A17,$AL$7:$AL$303,1)) -> 37383.42 | R17: =IF(OR($A17="",N(Q17)=0),"",C17/Q17-1) -> 2.2610425 | S17: =IF($A17="","",IFERROR(Q17/SUMIFS($AN$7:$AN$303,$AC$7:$AC$303,$A17,$AL$7:$AL$303,1),"")) -> 0.28191642 | T17: =IF(OR(E17="",S17=""),"",(E17-S17)*100) -> 35.639366 | U17: =IF(S17="","",IF(S17>=$L$4,"✔ Yes","✘ No")) -> ✘ No | V17: =IF($A17="","",COUNTIFS($AC$7:$AC$303,$A17,$AQ$7:$AQ$303,1,$AL$7:$AL$303,1)&" of "&COUNTIFS($AC$7:$AC$303,$A17,$AP$7:$AP$303,1,$AL$7:$AL$303,1)) -> 0 of 15 | W17: =IF($A17="","",IFERROR(SUMIFS($AM$7:$AM$303,$AC$7:$AC$303,$A17,$AR$7:$AR$303,1,$AL$7:$AL$303,1)/SUMIFS($AO$7:$AO$303,$AC$7:$AC$303,$A17,$AR$7:$AR$303,1,$AL$7:$AL$303,1)-1,"")) -> -0.31490518 | X17: =IF($A17="","",COUNTIFS($AC$7:$AC$303,$A17,$AS$7:$AS$303,1,$AL$7:$AL$303,1)&" of "&COUNTIFS($AC$7:$AC$303,$A17,$AR$7:$AR$303,1,$AL$7:$AL$303,1)) -> 2 of 8 | AB17: =IF('Sales Dashboard'!AW16="","",'Sales Dashboard'!AW16) -> HAMAHMAL | AC17: =IF(AB17="","",'Sales Dashboard'!AN16) -> Ahlam Al Zahrani | AD17: =IF(AB17="","",'Sales Dashboard'!AO16) -> Jeddah | AE17: {=IF(OR(AB17="",NOT(ISNUMBER('Sales Dashboard'!BF16))),0,SUMPRODUCT((IFERROR(--'Sales and count'!$G$2:$CC$2,0)=$C$4)*('Sales and count'!$G$3:$CC$3="Total"),INDEX('Sales and count'!$G$4:$CC$300,'Sales Dashboard'!BF16,0)))} -> 9670.21 | AF17: {=IF(OR(AB17="",NOT(ISNUMBER('Sales Dashboard'!BG16))),0,SUMPRODUCT(('TY Sales Target'!$K$2:$AO$2=$C$4)*1,INDEX('TY Sales Target'!$K$5:$AO$300,'Sales Dashboard'!BG16,0)))} -> 11905.025 | AG17: {=IF(AB17="",0,SUMPRODUCT((TRIM('LY Sales '!$B$5:$B$200)=AB17)*('LY Sales '!$C$2:$AG$2=EDATE($C$4,-12)),'LY Sales '!$C$5:$AG$200))} -> 0 | AH17: =--AND(AB17<>"",AF17>0) -> 1 | AI17: =--AND(AH17=1,AE17>=AF17*$L$4) -> 1 | AJ17: =--AND(AB17<>"",AG17>0) -> 0 | AK17: =--AND(AJ17=1,AE17>=AG17*$O$4) -> 0 | AL17: =--AND(AC17<>"",AC17<>"No assignment",AC17<>"Unassigned") -> 1 | AM17: {=IF(OR(AB17="",NOT(ISNUMBER('Sales Dashboard'!BF16))),0,SUMPRODUCT((IFERROR(--'Sales and count'!$G$2:$CC$2,0)=$F$4)*('Sales and count'!$G$3:$CC$3="Total"),INDEX('Sales and count'!$G$4:$CC$300,'Sales Dashboard'!BF16,0)))} -> 5586.2 | AN17: {=IF(OR(AB17="",NOT(ISNUMBER('Sales Dashboard'!BG16))),0,SUMPRODUCT(('TY Sales Target'!$K$2:$AO$2=$F$4)*1,INDEX('TY Sales Target'!$K$5:$AO$300,'Sales Dashboard'!BG16,0)))} -> 8265.8054 | AO17: {=IF(AB17="",0,SUMPRODUCT((TRIM('LY Sales '!$B$5:$B$200)=AB17)*('LY Sales '!$C$2:$AG$2=EDATE($F$4,-12)),'LY Sales '!$C$5:$AG$200))} -> 0 | AP17: =--AND(AB17<>"",AN17>0) -> 1 | AQ17: =--AND(AP17=1,AM17>=AN17*$L$4) -> 0 | AR17: =--AND(AB17<>"",AO17>0) -> 0 | AS17: =--AND(AR17=1,AM17>=AO17*$O$4) -> 0 | AU17: 46307
A18: {=IFERROR(INDEX(_xlfn._xlws.SORT(_xlfn.UNIQUE(_xlfn._xlws.FILTER($AC$7:$AC$303,$AL$7:$AL$303=1))),ROWS($A$16:A18)),"")} -> Hamzah Al Makhadam | B18: =IF($A18="","",COUNTIFS($AC$7:$AC$303,$A18,$AL$7:$AL$303,1)) -> 17 | C18: =IF($A18="","",SUMIFS($AE$7:$AE$303,$AC$7:$AC$303,$A18,$AL$7:$AL$303,1)) -> 192745.74 | D18: =IF($A18="","",SUMIFS($AF$7:$AF$303,$AC$7:$AC$303,$A18,$AL$7:$AL$303,1)) -> 269610.81 | E18: =IF(OR($A18="",N(D18)=0),"",C18/D18) -> 0.7149036 | F18: =IF(OR($A18="",N(D18)=0),"",IF(C18>=D18*$L$4,"✔ Yes","✘ No")) -> ✘ No | G18: =IF($A18="","",COUNTIFS($AC$7:$AC$303,$A18,$AH$7:$AH$303,1,$AL$7:$AL$303,1)) -> 17 | H18: =IF($A18="","",COUNTIFS($AC$7:$AC$303,$A18,$AI$7:$AI$303,1,$AL$7:$AL$303,1)) -> 3 | I18: =IF($A18="","",H18&" of "&G18) -> 3 of 17 | J18: =IF($A18="","",COUNTIFS($AC$7:$AC$303,$A18,$AJ$7:$AJ$303,1,$AL$7:$AL$303,1)) -> 13 | K18: =IF($A18="","",SUMIFS($AE$7:$AE$303,$AC$7:$AC$303,$A18,$AJ$7:$AJ$303,1,$AL$7:$AL$303,1)) -> 168230.21 | L18: =IF($A18="","",SUMIFS($AG$7:$AG$303,$AC$7:$AC$303,$A18,$AJ$7:$AJ$303,1,$AL$7:$AL$303,1)) -> 183964.16 | M18: =IF(OR($A18="",N(L18)=0),"",K18/L18-1) -> -0.085527257 | N18: =IF(OR($A18="",N(L18)=0),"",IF(K18>=L18*$O$4,"✔ Yes","✘ No")) -> ✘ No | O18: =IF($A18="","",COUNTIFS($AC$7:$AC$303,$A18,$AK$7:$AK$303,1,$AL$7:$AL$303,1)) -> 7 | P18: =IF($A18="","",O18&" of "&J18) -> 7 of 13 | Q18: =IF($A18="","",SUMIFS($AM$7:$AM$303,$AC$7:$AC$303,$A18,$AL$7:$AL$303,1)) -> 87053.21 | R18: =IF(OR($A18="",N(Q18)=0),"",C18/Q18-1) -> 1.2141141 | S18: =IF($A18="","",IFERROR(Q18/SUMIFS($AN$7:$AN$303,$AC$7:$AC$303,$A18,$AL$7:$AL$303,1),"")) -> 0.46504246 | T18: =IF(OR(E18="",S18=""),"",(E18-S18)*100) -> 24.986114 | U18: =IF(S18="","",IF(S18>=$L$4,"✔ Yes","✘ No")) -> ✘ No | V18: =IF($A18="","",COUNTIFS($AC$7:$AC$303,$A18,$AQ$7:$AQ$303,1,$AL$7:$AL$303,1)&" of "&COUNTIFS($AC$7:$AC$303,$A18,$AP$7:$AP$303,1,$AL$7:$AL$303,1)) -> 0 of 17 | W18: =IF($A18="","",IFERROR(SUMIFS($AM$7:$AM$303,$AC$7:$AC$303,$A18,$AR$7:$AR$303,1,$AL$7:$AL$303,1)/SUMIFS($AO$7:$AO$303,$AC$7:$AC$303,$A18,$AR$7:$AR$303,1,$AL$7:$AL$303,1)-1,"")) -> -0.20141824 | X18: =IF($A18="","",COUNTIFS($AC$7:$AC$303,$A18,$AS$7:$AS$303,1,$AL$7:$AL$303,1)&" of "&COUNTIFS($AC$7:$AC$303,$A18,$AR$7:$AR$303,1,$AL$7:$AL$303,1)) -> 6 of 13 | AB18: =IF('Sales Dashboard'!AW17="","",'Sales Dashboard'!AW17) -> HAMANRMAD | AC18: =IF(AB18="","",'Sales Dashboard'!AN17) -> Mohammed Haidar | AD18: =IF(AB18="","",'Sales Dashboard'!AO17) -> Madinah | AE18: {=IF(OR(AB18="",NOT(ISNUMBER('Sales Dashboard'!BF17))),0,SUMPRODUCT((IFERROR(--'Sales and count'!$G$2:$CC$2,0)=$C$4)*('Sales and count'!$G$3:$CC$3="Total"),INDEX('Sales and count'!$G$4:$CC$300,'Sales Dashboard'!BF17,0)))} -> 1802.04 | AF18: {=IF(OR(AB18="",NOT(ISNUMBER('Sales Dashboard'!BG17))),0,SUMPRODUCT(('TY Sales Target'!$K$2:$AO$2=$C$4)*1,INDEX('TY Sales Target'!$K$5:$AO$300,'Sales Dashboard'!BG17,0)))} -> 4964.6486 | AG18: {=IF(AB18="",0,SUMPRODUCT((TRIM('LY Sales '!$B$5:$B$200)=AB18)*('LY Sales '!$C$2:$AG$2=EDATE($C$4,-12)),'LY Sales '!$C$5:$AG$200))} -> 0 | AH18: =--AND(AB18<>"",AF18>0) -> 1 | AI18: =--AND(AH18=1,AE18>=AF18*$L$4) -> 0 | AJ18: =--AND(AB18<>"",AG18>0) -> 0 | AK18: =--AND(AJ18=1,AE18>=AG18*$O$4) -> 0 | AL18: =--AND(AC18<>"",AC18<>"No assignment",AC18<>"Unassigned") -> 1 | AM18: {=IF(OR(AB18="",NOT(ISNUMBER('Sales Dashboard'!BF17))),0,SUMPRODUCT((IFERROR(--'Sales and count'!$G$2:$CC$2,0)=$F$4)*('Sales and count'!$G$3:$CC$3="Total"),INDEX('Sales and count'!$G$4:$CC$300,'Sales Dashboard'!BF17,0)))} -> 2532 | AN18: {=IF(OR(AB18="",NOT(ISNUMBER('Sales Dashboard'!BG17))),0,SUMPRODUCT(('TY Sales Target'!$K$2:$AO$2=$F$4)*1,INDEX('TY Sales Target'!$K$5:$AO$300,'Sales Dashboard'!BG17,0)))} -> 3447.0167 | AO18: {=IF(AB18="",0,SUMPRODUCT((TRIM('LY Sales '!$B$5:$B$200)=AB18)*('LY Sales '!$C$2:$AG$2=EDATE($F$4,-12)),'LY Sales '!$C$5:$AG$200))} -> 0 | AP18: =--AND(AB18<>"",AN18>0) -> 1 | AQ18: =--AND(AP18=1,AM18>=AN18*$L$4) -> 0 | AR18: =--AND(AB18<>"",AO18>0) -> 0 | AS18: =--AND(AR18=1,AM18>=AO18*$O$4) -> 0 | AU18: 46308
A19: {=IFERROR(INDEX(_xlfn._xlws.SORT(_xlfn.UNIQUE(_xlfn._xlws.FILTER($AC$7:$AC$303,$AL$7:$AL$303=1))),ROWS($A$16:A19)),"")} -> Lina Al Ghathami | B19: =IF($A19="","",COUNTIFS($AC$7:$AC$303,$A19,$AL$7:$AL$303,1)) -> 15 | C19: =IF($A19="","",SUMIFS($AE$7:$AE$303,$AC$7:$AC$303,$A19,$AL$7:$AL$303,1)) -> 118982.22 | D19: =IF($A19="","",SUMIFS($AF$7:$AF$303,$AC$7:$AC$303,$A19,$AL$7:$AL$303,1)) -> 188605.99 | E19: =IF(OR($A19="",N(D19)=0),"",C19/D19) -> 0.63085071 | F19: =IF(OR($A19="",N(D19)=0),"",IF(C19>=D19*$L$4,"✔ Yes","✘ No")) -> ✘ No | G19: =IF($A19="","",COUNTIFS($AC$7:$AC$303,$A19,$AH$7:$AH$303,1,$AL$7:$AL$303,1)) -> 15 | H19: =IF($A19="","",COUNTIFS($AC$7:$AC$303,$A19,$AI$7:$AI$303,1,$AL$7:$AL$303,1)) -> 2 | I19: =IF($A19="","",H19&" of "&G19) -> 2 of 15 | J19: =IF($A19="","",COUNTIFS($AC$7:$AC$303,$A19,$AJ$7:$AJ$303,1,$AL$7:$AL$303,1)) -> 9 | K19: =IF($A19="","",SUMIFS($AE$7:$AE$303,$AC$7:$AC$303,$A19,$AJ$7:$AJ$303,1,$AL$7:$AL$303,1)) -> 80793.48 | L19: =IF($A19="","",SUMIFS($AG$7:$AG$303,$AC$7:$AC$303,$A19,$AJ$7:$AJ$303,1,$AL$7:$AL$303,1)) -> 128547.69 | M19: =IF(OR($A19="",N(L19)=0),"",K19/L19-1) -> -0.37149022 | N19: =IF(OR($A19="",N(L19)=0),"",IF(K19>=L19*$O$4,"✔ Yes","✘ No")) -> ✘ No | O19: =IF($A19="","",COUNTIFS($AC$7:$AC$303,$A19,$AK$7:$AK$303,1,$AL$7:$AL$303,1)) -> 2 | P19: =IF($A19="","",O19&" of "&J19) -> 2 of 9 | Q19: =IF($A19="","",SUMIFS($AM$7:$AM$303,$AC$7:$AC$303,$A19,$AL$7:$AL$303,1)) -> 67339.65 | R19: =IF(OR($A19="",N(Q19)=0),"",C19/Q19-1) -> 0.76689692 | S19: =IF($A19="","",IFERROR(Q19/SUMIFS($AN$7:$AN$303,$AC$7:$AC$303,$A19,$AL$7:$AL$303,1),"")) -> 0.51423367 | T19: =IF(OR(E19="",S19=""),"",(E19-S19)*100) -> 11.661704 | U19: =IF(S19="","",IF(S19>=$L$4,"✔ Yes","✘ No")) -> ✘ No | V19: =IF($A19="","",COUNTIFS($AC$7:$AC$303,$A19,$AQ$7:$AQ$303,1,$AL$7:$AL$303,1)&" of "&COUNTIFS($AC$7:$AC$303,$A19,$AP$7:$AP$303,1,$AL$7:$AL$303,1)) -> 1 of 15 | W19: =IF($A19="","",IFERROR(SUMIFS($AM$7:$AM$303,$AC$7:$AC$303,$A19,$AR$7:$AR$303,1,$AL$7:$AL$303,1)/SUMIFS($AO$7:$AO$303,$AC$7:$AC$303,$A19,$AR$7:$AR$303,1,$AL$7:$AL$303,1)-1,"")) -> -0.21294277 | X19: =IF($A19="","",COUNTIFS($AC$7:$AC$303,$A19,$AS$7:$AS$303,1,$AL$7:$AL$303,1)&" of "&COUNTIFS($AC$7:$AC$303,$A19,$AR$7:$AR$303,1,$AL$7:$AL$303,1)) -> 4 of 10 | AB19: =IF('Sales Dashboard'!AW18="","",'Sales Dashboard'!AW18) -> HANJFRONT | AC19: =IF(AB19="","",'Sales Dashboard'!AN18) -> Ahmed Jaffari | AD19: =IF(AB19="","",'Sales Dashboard'!AO18) -> Najran | AE19: {=IF(OR(AB19="",NOT(ISNUMBER('Sales Dashboard'!BF18))),0,SUMPRODUCT((IFERROR(--'Sales and count'!$G$2:$CC$2,0)=$C$4)*('Sales and count'!$G$3:$CC$3="Total"),INDEX('Sales and count'!$G$4:$CC$300,'Sales Dashboard'!BF18,0)))} -> 2380.1 | AF19: {=IF(OR(AB19="",NOT(ISNUMBER('Sales Dashboard'!BG18))),0,SUMPRODUCT(('TY Sales Target'!$K$2:$AO$2=$C$4)*1,INDEX('TY Sales Target'!$K$5:$AO$300,'Sales Dashboard'!BG18,0)))} -> 3039.5807 | AG19: {=IF(AB19="",0,SUMPRODUCT((TRIM('LY Sales '!$B$5:$B$200)=AB19)*('LY Sales '!$C$2:$AG$2=EDATE($C$4,-12)),'LY Sales '!$C$5:$AG$200))} -> 0 | AH19: =--AND(AB19<>"",AF19>0) -> 1 | AI19: =--AND(AH19=1,AE19>=AF19*$L$4) -> 0 | AJ19: =--AND(AB19<>"",AG19>0) -> 0 | AK19: =--AND(AJ19=1,AE19>=AG19*$O$4) -> 0 | AL19: =--AND(AC19<>"",AC19<>"No assignment",AC19<>"Unassigned") -> 1 | AM19: {=IF(OR(AB19="",NOT(ISNUMBER('Sales Dashboard'!BF18))),0,SUMPRODUCT((IFERROR(--'Sales and count'!$G$2:$CC$2,0)=$F$4)*('Sales and count'!$G$3:$CC$3="Total"),INDEX('Sales and count'!$G$4:$CC$300,'Sales Dashboard'!BF18,0)))} -> 1419.11 | AN19: {=IF(OR(AB19="",NOT(ISNUMBER('Sales Dashboard'!BG18))),0,SUMPRODUCT(('TY Sales Target'!$K$2:$AO$2=$F$4)*1,INDEX('TY Sales Target'!$K$5:$AO$300,'Sales Dashboard'!BG18,0)))} -> 2110.4184 | AO19: {=IF(AB19="",0,SUMPRODUCT((TRIM('LY Sales '!$B$5:$B$200)=AB19)*('LY Sales '!$C$2:$AG$2=EDATE($F$4,-12)),'LY Sales '!$C$5:$AG$200))} -> 0 | AP19: =--AND(AB19<>"",AN19>0) -> 1 | AQ19: =--AND(AP19=1,AM19>=AN19*$L$4) -> 0 | AR19: =--AND(AB19<>"",AO19>0) -> 0 | AS19: =--AND(AR19=1,AM19>=AO19*$O$4) -> 0 | AU19: 46309
A20: {=IFERROR(INDEX(_xlfn._xlws.SORT(_xlfn.UNIQUE(_xlfn._xlws.FILTER($AC$7:$AC$303,$AL$7:$AL$303=1))),ROWS($A$16:A20)),"")} -> Maram Zamzami | B20: =IF($A20="","",COUNTIFS($AC$7:$AC$303,$A20,$AL$7:$AL$303,1)) -> 12 | C20: =IF($A20="","",SUMIFS($AE$7:$AE$303,$AC$7:$AC$303,$A20,$AL$7:$AL$303,1)) -> 134984.1 | D20: =IF($A20="","",SUMIFS($AF$7:$AF$303,$AC$7:$AC$303,$A20,$AL$7:$AL$303,1)) -> 216570.13 | E20: =IF(OR($A20="",N(D20)=0),"",C20/D20) -> 0.62328125 | F20: =IF(OR($A20="",N(D20)=0),"",IF(C20>=D20*$L$4,"✔ Yes","✘ No")) -> ✘ No | G20: =IF($A20="","",COUNTIFS($AC$7:$AC$303,$A20,$AH$7:$AH$303,1,$AL$7:$AL$303,1)) -> 12 | H20: =IF($A20="","",COUNTIFS($AC$7:$AC$303,$A20,$AI$7:$AI$303,1,$AL$7:$AL$303,1)) -> 2 | I20: =IF($A20="","",H20&" of "&G20) -> 2 of 12 | J20: =IF($A20="","",COUNTIFS($AC$7:$AC$303,$A20,$AJ$7:$AJ$303,1,$AL$7:$AL$303,1)) -> 5 | K20: =IF($A20="","",SUMIFS($AE$7:$AE$303,$AC$7:$AC$303,$A20,$AJ$7:$AJ$303,1,$AL$7:$AL$303,1)) -> 45473.05 | L20: =IF($A20="","",SUMIFS($AG$7:$AG$303,$AC$7:$AC$303,$A20,$AJ$7:$AJ$303,1,$AL$7:$AL$303,1)) -> 73622.34 | M20: =IF(OR($A20="",N(L20)=0),"",K20/L20-1) -> -0.38234712 | N20: =IF(OR($A20="",N(L20)=0),"",IF(K20>=L20*$O$4,"✔ Yes","✘ No")) -> ✘ No | O20: =IF($A20="","",COUNTIFS($AC$7:$AC$303,$A20,$AK$7:$AK$303,1,$AL$7:$AL$303,1)) -> 1 | P20: =IF($A20="","",O20&" of "&J20) -> 1 of 5 | Q20: =IF($A20="","",SUMIFS($AM$7:$AM$303,$AC$7:$AC$303,$A20,$AL$7:$AL$303,1)) -> 64601.89 | R20: =IF(OR($A20="",N(Q20)=0),"",C20/Q20-1) -> 1.089476 | S20: =IF($A20="","",IFERROR(Q20/SUMIFS($AN$7:$AN$303,$AC$7:$AC$303,$A20,$AL$7:$AL$303,1),"")) -> 0.42962722 | T20: =IF(OR(E20="",S20=""),"",(E20-S20)*100) -> 19.365403 | U20: =IF(S20="","",IF(S20>=$L$4,"✔ Yes","✘ No")) -> ✘ No | V20: =IF($A20="","",COUNTIFS($AC$7:$AC$303,$A20,$AQ$7:$AQ$303,1,$AL$7:$AL$303,1)&" of "&COUNTIFS($AC$7:$AC$303,$A20,$AP$7:$AP$303,1,$AL$7:$AL$303,1)) -> 0 of 12 | W20: =IF($A20="","",IFERROR(SUMIFS($AM$7:$AM$303,$AC$7:$AC$303,$A20,$AR$7:$AR$303,1,$AL$7:$AL$303,1)/SUMIFS($AO$7:$AO$303,$AC$7:$AC$303,$A20,$AR$7:$AR$303,1,$AL$7:$AL$303,1)-1,"")) -> -0.36207281 | X20: =IF($A20="","",COUNTIFS($AC$7:$AC$303,$A20,$AS$7:$AS$303,1,$AL$7:$AL$303,1)&" of "&COUNTIFS($AC$7:$AC$303,$A20,$AR$7:$AR$303,1,$AL$7:$AL$303,1)) -> 1 of 6 | AB20: =IF('Sales Dashboard'!AW19="","",'Sales Dashboard'!AW19) -> HADARALEMN | AC20: =IF(AB20="","",'Sales Dashboard'!AN19) -> Mohammed Haidar | AD20: =IF(AB20="","",'Sales Dashboard'!AO19) -> Madinah | AE20: {=IF(OR(AB20="",NOT(ISNUMBER('Sales Dashboard'!BF19))),0,SUMPRODUCT((IFERROR(--'Sales and count'!$G$2:$CC$2,0)=$C$4)*('Sales and count'!$G$3:$CC$3="Total"),INDEX('Sales and count'!$G$4:$CC$300,'Sales Dashboard'!BF19,0)))} -> 9144.24 | AF20: {=IF(OR(AB20="",NOT(ISNUMBER('Sales Dashboard'!BG19))),0,SUMPRODUCT(('TY Sales Target'!$K$2:$AO$2=$C$4)*1,INDEX('TY Sales Target'!$K$5:$AO$300,'Sales Dashboard'!BG19,0)))} -> 15552.521 | AG20: {=IF(AB20="",0,SUMPRODUCT((TRIM('LY Sales '!$B$5:$B$200)=AB20)*('LY Sales '!$C$2:$AG$2=EDATE($C$4,-12)),'LY Sales '!$C$5:$AG$200))} -> 0 | AH20: =--AND(AB20<>"",AF20>0) -> 1 | AI20: =--AND(AH20=1,AE20>=AF20*$L$4) -> 0 | AJ20: =--AND(AB20<>"",AG20>0) -> 0 | AK20: =--AND(AJ20=1,AE20>=AG20*$O$4) -> 0 | AL20: =--AND(AC20<>"",AC20<>"No assignment",AC20<>"Unassigned") -> 1 | AM20: {=IF(OR(AB20="",NOT(ISNUMBER('Sales Dashboard'!BF19))),0,SUMPRODUCT((IFERROR(--'Sales and count'!$G$2:$CC$2,0)=$F$4)*('Sales and count'!$G$3:$CC$3="Total"),INDEX('Sales and count'!$G$4:$CC$300,'Sales Dashboard'!BF19,0)))} -> 10233.69 | AN20: {=IF(OR(AB20="",NOT(ISNUMBER('Sales Dashboard'!BG19))),0,SUMPRODUCT(('TY Sales Target'!$K$2:$AO$2=$F$4)*1,INDEX('TY Sales Target'!$K$5:$AO$300,'Sales Dashboard'!BG19,0)))} -> 10798.307 | AO20: {=IF(AB20="",0,SUMPRODUCT((TRIM('LY Sales '!$B$5:$B$200)=AB20)*('LY Sales '!$C$2:$AG$2=EDATE($F$4,-12)),'LY Sales '!$C$5:$AG$200))} -> 0 | AP20: =--AND(AB20<>"",AN20>0) -> 1 | AQ20: =--AND(AP20=1,AM20>=AN20*$L$4) -> 1 | AR20: =--AND(AB20<>"",AO20>0) -> 0 | AS20: =--AND(AR20=1,AM20>=AO20*$O$4) -> 0 | AU20: 46310
A21: {=IFERROR(INDEX(_xlfn._xlws.SORT(_xlfn.UNIQUE(_xlfn._xlws.FILTER($AC$7:$AC$303,$AL$7:$AL$303=1))),ROWS($A$16:A21)),"")} -> Mohammed Haidar | B21: =IF($A21="","",COUNTIFS($AC$7:$AC$303,$A21,$AL$7:$AL$303,1)) -> 13 | C21: =IF($A21="","",SUMIFS($AE$7:$AE$303,$AC$7:$AC$303,$A21,$AL$7:$AL$303,1)) -> 61791.21 | D21: =IF($A21="","",SUMIFS($AF$7:$AF$303,$AC$7:$AC$303,$A21,$AL$7:$AL$303,1)) -> 115453.41 | E21: =IF(OR($A21="",N(D21)=0),"",C21/D21) -> 0.53520473 | F21: =IF(OR($A21="",N(D21)=0),"",IF(C21>=D21*$L$4,"✔ Yes","✘ No")) -> ✘ No | G21: =IF($A21="","",COUNTIFS($AC$7:$AC$303,$A21,$AH$7:$AH$303,1,$AL$7:$AL$303,1)) -> 13 | H21: =IF($A21="","",COUNTIFS($AC$7:$AC$303,$A21,$AI$7:$AI$303,1,$AL$7:$AL$303,1)) -> 1 | I21: =IF($A21="","",H21&" of "&G21) -> 1 of 13 | J21: =IF($A21="","",COUNTIFS($AC$7:$AC$303,$A21,$AJ$7:$AJ$303,1,$AL$7:$AL$303,1)) -> 4 | K21: =IF($A21="","",SUMIFS($AE$7:$AE$303,$AC$7:$AC$303,$A21,$AJ$7:$AJ$303,1,$AL$7:$AL$303,1)) -> 21762.28 | L21: =IF($A21="","",SUMIFS($AG$7:$AG$303,$AC$7:$AC$303,$A21,$AJ$7:$AJ$303,1,$AL$7:$AL$303,1)) -> 43205.08 | M21: =IF(OR($A21="",N(L21)=0),"",K21/L21-1) -> -0.49630275 | N21: =IF(OR($A21="",N(L21)=0),"",IF(K21>=L21*$O$4,"✔ Yes","✘ No")) -> ✘ No | O21: =IF($A21="","",COUNTIFS($AC$7:$AC$303,$A21,$AK$7:$AK$303,1,$AL$7:$AL$303,1)) -> 0 | P21: =IF($A21="","",O21&" of "&J21) -> 0 of 4 | Q21: =IF($A21="","",SUMIFS($AM$7:$AM$303,$AC$7:$AC$303,$A21,$AL$7:$AL$303,1)) -> 56026.73 | R21: =IF(OR($A21="",N(Q21)=0),"",C21/Q21-1) -> 0.10288803 | S21: =IF($A21="","",IFERROR(Q21/SUMIFS($AN$7:$AN$303,$AC$7:$AC$303,$A21,$AL$7:$AL$303,1),"")) -> 0.69892993 | T21: =IF(OR(E21="",S21=""),"",(E21-S21)*100) -> -16.37252 | U21: =IF(S21="","",IF(S21>=$L$4,"✔ Yes","✘ No")) -> ✘ No | V21: =IF($A21="","",COUNTIFS($AC$7:$AC$303,$A21,$AQ$7:$AQ$303,1,$AL$7:$AL$303,1)&" of "&COUNTIFS($AC$7:$AC$303,$A21,$AP$7:$AP$303,1,$AL$7:$AL$303,1)) -> 3 of 13 | W21: =IF($A21="","",IFERROR(SUMIFS($AM$7:$AM$303,$AC$7:$AC$303,$A21,$AR$7:$AR$303,1,$AL$7:$AL$303,1)/SUMIFS($AO$7:$AO$303,$AC$7:$AC$303,$A21,$AR$7:$AR$303,1,$AL$7:$AL$303,1)-1,"")) -> -0.25829836 | X21: =IF($A21="","",COUNTIFS($AC$7:$AC$303,$A21,$AS$7:$AS$303,1,$AL$7:$AL$303,1)&" of "&COUNTIFS($AC$7:$AC$303,$A21,$AR$7:$AR$303,1,$AL$7:$AL$303,1)) -> 2 of 4 | AB21: =IF('Sales Dashboard'!AW20="","",'Sales Dashboard'!AW20) -> HASHKAVNUE | AC21: =IF(AB21="","",'Sales Dashboard'!AN20) -> Hamzah Al Makhadam | AD21: =IF(AB21="","",'Sales Dashboard'!AO20) -> Khobar | AE21: {=IF(OR(AB21="",NOT(ISNUMBER('Sales Dashboard'!BF20))),0,SUMPRODUCT((IFERROR(--'Sales and count'!$G$2:$CC$2,0)=$C$4)*('Sales and count'!$G$3:$CC$3="Total"),INDEX('Sales and count'!$G$4:$CC$300,'Sales Dashboard'!BF20,0)))} -> 34314.83 | AF21: {=IF(OR(AB21="",NOT(ISNUMBER('Sales Dashboard'!BG20))),0,SUMPRODUCT(('TY Sales Target'!$K$2:$AO$2=$C$4)*1,INDEX('TY Sales Target'!$K$5:$AO$300,'Sales Dashboard'!BG20,0)))} -> 43719.303 | AG21: {=IF(AB21="",0,SUMPRODUCT((TRIM('LY Sales '!$B$5:$B$200)=AB21)*('LY Sales '!$C$2:$AG$2=EDATE($C$4,-12)),'LY Sales '!$C$5:$AG$200))} -> 31505.57 | AH21: =--AND(AB21<>"",AF21>0) -> 1 | AI21: =--AND(AH21=1,AE21>=AF21*$L$4) -> 0 | AJ21: =--AND(AB21<>"",AG21>0) -> 1 | AK21: =--AND(AJ21=1,AE21>=AG21*$O$4) -> 1 | AL21: =--AND(AC21<>"",AC21<>"No assignment",AC21<>"Unassigned") -> 1 | AM21: {=IF(OR(AB21="",NOT(ISNUMBER('Sales Dashboard'!BF20))),0,SUMPRODUCT((IFERROR(--'Sales and count'!$G$2:$CC$2,0)=$F$4)*('Sales and count'!$G$3:$CC$3="Total"),INDEX('Sales and count'!$G$4:$CC$300,'Sales Dashboard'!BF20,0)))} -> 18766.22 | AN21: {=IF(OR(AB21="",NOT(ISNUMBER('Sales Dashboard'!BG20))),0,SUMPRODUCT(('TY Sales Target'!$K$2:$AO$2=$F$4)*1,INDEX('TY Sales Target'!$K$5:$AO$300,'Sales Dashboard'!BG20,0)))} -> 30354.851 | AO21: {=IF(AB21="",0,SUMPRODUCT((TRIM('LY Sales '!$B$5:$B$200)=AB21)*('LY Sales '!$C$2:$AG$2=EDATE($F$4,-12)),'LY Sales '!$C$5:$AG$200))} -> 22787.54 | AP21: =--AND(AB21<>"",AN21>0) -> 1 | AQ21: =--AND(AP21=1,AM21>=AN21*$L$4) -> 0 | AR21: =--AND(AB21<>"",AO21>0) -> 1 | AS21: =--AND(AR21=1,AM21>=AO21*$O$4) -> 0 | AU21: 46311
A22: {=IFERROR(INDEX(_xlfn._xlws.SORT(_xlfn.UNIQUE(_xlfn._xlws.FILTER($AC$7:$AC$303,$AL$7:$AL$303=1))),ROWS($A$16:A22)),"")} -> Mohammed Sanad | B22: =IF($A22="","",COUNTIFS($AC$7:$AC$303,$A22,$AL$7:$AL$303,1)) -> 15 | C22: =IF($A22="","",SUMIFS($AE$7:$AE$303,$AC$7:$AC$303,$A22,$AL$7:$AL$303,1)) -> 109737.22 | D22: =IF($A22="","",SUMIFS($AF$7:$AF$303,$AC$7:$AC$303,$A22,$AL$7:$AL$303,1)) -> 180145.82 | E22: =IF(OR($A22="",N(D22)=0),"",C22/D22) -> 0.60915774 | F22: =IF(OR($A22="",N(D22)=0),"",IF(C22>=D22*$L$4,"✔ Yes","✘ No")) -> ✘ No | G22: =IF($A22="","",COUNTIFS($AC$7:$AC$303,$A22,$AH$7:$AH$303,1,$AL$7:$AL$303,1)) -> 15 | H22: =IF($A22="","",COUNTIFS($AC$7:$AC$303,$A22,$AI$7:$AI$303,1,$AL$7:$AL$303,1)) -> 2 | I22: =IF($A22="","",H22&" of "&G22) -> 2 of 15 | J22: =IF($A22="","",COUNTIFS($AC$7:$AC$303,$A22,$AJ$7:$AJ$303,1,$AL$7:$AL$303,1)) -> 7 | K22: =IF($A22="","",SUMIFS($AE$7:$AE$303,$AC$7:$AC$303,$A22,$AJ$7:$AJ$303,1,$AL$7:$AL$303,1)) -> 59683.35 | L22: =IF($A22="","",SUMIFS($AG$7:$AG$303,$AC$7:$AC$303,$A22,$AJ$7:$AJ$303,1,$AL$7:$AL$303,1)) -> 99070.72 | M22: =IF(OR($A22="",N(L22)=0),"",K22/L22-1) -> -0.39756822 | N22: =IF(OR($A22="",N(L22)=0),"",IF(K22>=L22*$O$4,"✔ Yes","✘ No")) -> ✘ No | O22: =IF($A22="","",COUNTIFS($AC$7:$AC$303,$A22,$AK$7:$AK$303,1,$AL$7:$AL$303,1)) -> 0 | P22: =IF($A22="","",O22&" of "&J22) -> 0 of 7 | Q22: =IF($A22="","",SUMIFS($AM$7:$AM$303,$AC$7:$AC$303,$A22,$AL$7:$AL$303,1)) -> 53592.29 | R22: =IF(OR($A22="",N(Q22)=0),"",C22/Q22-1) -> 1.0476307 | S22: =IF($A22="","",IFERROR(Q22/SUMIFS($AN$7:$AN$303,$AC$7:$AC$303,$A22,$AL$7:$AL$303,1),"")) -> 0.42847279 | T22: =IF(OR(E22="",S22=""),"",(E22-S22)*100) -> 18.068495 | U22: =IF(S22="","",IF(S22>=$L$4,"✔ Yes","✘ No")) -> ✘ No | V22: =IF($A22="","",COUNTIFS($AC$7:$AC$303,$A22,$AQ$7:$AQ$303,1,$AL$7:$AL$303,1)&" of "&COUNTIFS($AC$7:$AC$303,$A22,$AP$7:$AP$303,1,$AL$7:$AL$303,1)) -> 0 of 15 | W22: =IF($A22="","",IFERROR(SUMIFS($AM$7:$AM$303,$AC$7:$AC$303,$A22,$AR$7:$AR$303,1,$AL$7:$AL$303,1)/SUMIFS($AO$7:$AO$303,$AC$7:$AC$303,$A22,$AR$7:$AR$303,1,$AL$7:$AL$303,1)-1,"")) -> -0.45349762 | X22: =IF($A22="","",COUNTIFS($AC$7:$AC$303,$A22,$AS$7:$AS$303,1,$AL$7:$AL$303,1)&" of "&COUNTIFS($AC$7:$AC$303,$A22,$AR$7:$AR$303,1,$AL$7:$AL$303,1)) -> 1 of 9 | AB22: =IF('Sales Dashboard'!AW21="","",'Sales Dashboard'!AW21) -> HAMAYASMAD | AC22: =IF(AB22="","",'Sales Dashboard'!AN21) -> Mohammed Haidar | AD22: =IF(AB22="","",'Sales Dashboard'!AO21) -> Madinah | AE22: {=IF(OR(AB22="",NOT(ISNUMBER('Sales Dashboard'!BF21))),0,SUMPRODUCT((IFERROR(--'Sales and count'!$G$2:$CC$2,0)=$C$4)*('Sales and count'!$G$3:$CC$3="Total"),INDEX('Sales and count'!$G$4:$CC$300,'Sales Dashboard'!BF21,0)))} -> 3502.08 | AF22: {=IF(OR(AB22="",NOT(ISNUMBER('Sales Dashboard'!BG21))),0,SUMPRODUCT(('TY Sales Target'!$K$2:$AO$2=$C$4)*1,INDEX('TY Sales Target'!$K$5:$AO$300,'Sales Dashboard'!BG21,0)))} -> 6839.0567 | AG22: {=IF(AB22="",0,SUMPRODUCT((TRIM('LY Sales '!$B$5:$B$200)=AB22)*('LY Sales '!$C$2:$AG$2=EDATE($C$4,-12)),'LY Sales '!$C$5:$AG$200))} -> 3546.08 | AH22: =--AND(AB22<>"",AF22>0) -> 1 | AI22: =--AND(AH22=1,AE22>=AF22*$L$4) -> 0 | AJ22: =--AND(AB22<>"",AG22>0) -> 1 | AK22: =--AND(AJ22=1,AE22>=AG22*$O$4) -> 0 | AL22: =--AND(AC22<>"",AC22<>"No assignment",AC22<>"Unassigned") -> 1 | AM22: {=IF(OR(AB22="",NOT(ISNUMBER('Sales Dashboard'!BF21))),0,SUMPRODUCT((IFERROR(--'Sales and count'!$G$2:$CC$2,0)=$F$4)*('Sales and count'!$G$3:$CC$3="Total"),INDEX('Sales and count'!$G$4:$CC$300,'Sales Dashboard'!BF21,0)))} -> 3774.24 | AN22: {=IF(OR(AB22="",NOT(ISNUMBER('Sales Dashboard'!BG21))),0,SUMPRODUCT(('TY Sales Target'!$K$2:$AO$2=$F$4)*1,INDEX('TY Sales Target'!$K$5:$AO$300,'Sales Dashboard'!BG21,0)))} -> 4748.4414 | AO22: {=IF(AB22="",0,SUMPRODUCT((TRIM('LY Sales '!$B$5:$B$200)=AB22)*('LY Sales '!$C$2:$AG$2=EDATE($F$4,-12)),'LY Sales '!$C$5:$AG$200))} -> 2972.06 | AP22: =--AND(AB22<>"",AN22>0) -> 1 | AQ22: =--AND(AP22=1,AM22>=AN22*$L$4) -> 0 | AR22: =--AND(AB22<>"",AO22>0) -> 1 | AS22: =--AND(AR22=1,AM22>=AO22*$O$4) -> 1 | AU22: 46312
A23: {=IFERROR(INDEX(_xlfn._xlws.SORT(_xlfn.UNIQUE(_xlfn._xlws.FILTER($AC$7:$AC$303,$AL$7:$AL$303=1))),ROWS($A$16:A23)),"")} -> Saleh Bin Hoiel | B23: =IF($A23="","",COUNTIFS($AC$7:$AC$303,$A23,$AL$7:$AL$303,1)) -> 14 | C23: =IF($A23="","",SUMIFS($AE$7:$AE$303,$AC$7:$AC$303,$A23,$AL$7:$AL$303,1)) -> 127723.26 | D23: =IF($A23="","",SUMIFS($AF$7:$AF$303,$AC$7:$AC$303,$A23,$AL$7:$AL$303,1)) -> 180173.37 | E23: =IF(OR($A23="",N(D23)=0),"",C23/D23) -> 0.70889089 | F23: =IF(OR($A23="",N(D23)=0),"",IF(C23>=D23*$L$4,"✔ Yes","✘ No")) -> ✘ No | G23: =IF($A23="","",COUNTIFS($AC$7:$AC$303,$A23,$AH$7:$AH$303,1,$AL$7:$AL$303,1)) -> 14 | H23: =IF($A23="","",COUNTIFS($AC$7:$AC$303,$A23,$AI$7:$AI$303,1,$AL$7:$AL$303,1)) -> 4 | I23: =IF($A23="","",H23&" of "&G23) -> 4 of 14 | J23: =IF($A23="","",COUNTIFS($AC$7:$AC$303,$A23,$AJ$7:$AJ$303,1,$AL$7:$AL$303,1)) -> 8 | K23: =IF($A23="","",SUMIFS($AE$7:$AE$303,$AC$7:$AC$303,$A23,$AJ$7:$AJ$303,1,$AL$7:$AL$303,1)) -> 92134.59 | L23: =IF($A23="","",SUMIFS($AG$7:$AG$303,$AC$7:$AC$303,$A23,$AJ$7:$AJ$303,1,$AL$7:$AL$303,1)) -> 111362.02 | M23: =IF(OR($A23="",N(L23)=0),"",K23/L23-1) -> -0.17265698 | N23: =IF(OR($A23="",N(L23)=0),"",IF(K23>=L23*$O$4,"✔ Yes","✘ No")) -> ✘ No | O23: =IF($A23="","",COUNTIFS($AC$7:$AC$303,$A23,$AK$7:$AK$303,1,$AL$7:$AL$303,1)) -> 2 | P23: =IF($A23="","",O23&" of "&J23) -> 2 of 8 | Q23: =IF($A23="","",SUMIFS($AM$7:$AM$303,$AC$7:$AC$303,$A23,$AL$7:$AL$303,1)) -> 50817.16 | R23: =IF(OR($A23="",N(Q23)=0),"",C23/Q23-1) -> 1.5133884 | S23: =IF($A23="","",IFERROR(Q23/SUMIFS($AN$7:$AN$303,$AC$7:$AC$303,$A23,$AL$7:$AL$303,1),"")) -> 0.40622338 | T23: =IF(OR(E23="",S23=""),"",(E23-S23)*100) -> 30.266751 | U23: =IF(S23="","",IF(S23>=$L$4,"✔ Yes","✘ No")) -> ✘ No | V23: =IF($A23="","",COUNTIFS($AC$7:$AC$303,$A23,$AQ$7:$AQ$303,1,$AL$7:$AL$303,1)&" of "&COUNTIFS($AC$7:$AC$303,$A23,$AP$7:$AP$303,1,$AL$7:$AL$303,1)) -> 2 of 14 | W23: =IF($A23="","",IFERROR(SUMIFS($AM$7:$AM$303,$AC$7:$AC$303,$A23,$AR$7:$AR$303,1,$AL$7:$AL$303,1)/SUMIFS($AO$7:$AO$303,$AC$7:$AC$303,$A23,$AR$7:$AR$303,1,$AL$7:$AL$303,1)-1,"")) -> -0.16554937 | X23: =IF($A23="","",COUNTIFS($AC$7:$AC$303,$A23,$AS$7:$AS$303,1,$AL$7:$AL$303,1)&" of "&COUNTIFS($AC$7:$AC$303,$A23,$AR$7:$AR$303,1,$AL$7:$AL$303,1)) -> 2 of 8 | AB23: =IF('Sales Dashboard'!AW22="","",'Sales Dashboard'!AW22) -> HAWADILABN | AC23: =IF(AB23="","",'Sales Dashboard'!AN22) -> Mohammed Sanad | AD23: =IF(AB23="","",'Sales Dashboard'!AO22) -> Riyadh | AE23: {=IF(OR(AB23="",NOT(ISNUMBER('Sales Dashboard'!BF22))),0,SUMPRODUCT((IFERROR(--'Sales and count'!$G$2:$CC$2,0)=$C$4)*('Sales and count'!$G$3:$CC$3="Total"),INDEX('Sales and count'!$G$4:$CC$300,'Sales Dashboard'!BF22,0)))} -> 9168.13 | AF23: {=IF(OR(AB23="",NOT(ISNUMBER('Sales Dashboard'!BG22))),0,SUMPRODUCT(('TY Sales Target'!$K$2:$AO$2=$C$4)*1,INDEX('TY Sales Target'!$K$5:$AO$300,'Sales Dashboard'!BG22,0)))} -> 14488.668 | AG23: {=IF(AB23="",0,SUMPRODUCT((TRIM('LY Sales '!$B$5:$B$200)=AB23)*('LY Sales '!$C$2:$AG$2=EDATE($C$4,-12)),'LY Sales '!$C$5:$AG$200))} -> 0 | AH23: =--AND(AB23<>"",AF23>0) -> 1 | AI23: =--AND(AH23=1,AE23>=AF23*$L$4) -> 0 | AJ23: =--AND(AB23<>"",AG23>0) -> 0 | AK23: =--AND(AJ23=1,AE23>=AG23*$O$4) -> 0 | AL23: =--AND(AC23<>"",AC23<>"No assignment",AC23<>"Unassigned") -> 1 | AM23: {=IF(OR(AB23="",NOT(ISNUMBER('Sales Dashboard'!BF22))),0,SUMPRODUCT((IFERROR(--'Sales and count'!$G$2:$CC$2,0)=$F$4)*('Sales and count'!$G$3:$CC$3="Total"),INDEX('Sales and count'!$G$4:$CC$300,'Sales Dashboard'!BF22,0)))} -> 3873.27 | AN23: {=IF(OR(AB23="",NOT(ISNUMBER('Sales Dashboard'!BG22))),0,SUMPRODUCT(('TY Sales Target'!$K$2:$AO$2=$F$4)*1,INDEX('TY Sales Target'!$K$5:$AO$300,'Sales Dashboard'!BG22,0)))} -> 10059.661 | AO23: {=IF(AB23="",0,SUMPRODUCT((TRIM('LY Sales '!$B$5:$B$200)=AB23)*('LY Sales '!$C$2:$AG$2=EDATE($F$4,-12)),'LY Sales '!$C$5:$AG$200))} -> 0 | AP23: =--AND(AB23<>"",AN23>0) -> 1 | AQ23: =--AND(AP23=1,AM23>=AN23*$L$4) -> 0 | AR23: =--AND(AB23<>"",AO23>0) -> 0 | AS23: =--AND(AR23=1,AM23>=AO23*$O$4) -> 0 | AU23: 46313
A24: {=IFERROR(INDEX(_xlfn._xlws.SORT(_xlfn.UNIQUE(_xlfn._xlws.FILTER($AC$7:$AC$303,$AL$7:$AL$303=1))),ROWS($A$16:A24)),"")} | B24: =IF($A24="","",COUNTIFS($AC$7:$AC$303,$A24,$AL$7:$AL$303,1)) | C24: =IF($A24="","",SUMIFS($AE$7:$AE$303,$AC$7:$AC$303,$A24,$AL$7:$AL$303,1)) | D24: =IF($A24="","",SUMIFS($AF$7:$AF$303,$AC$7:$AC$303,$A24,$AL$7:$AL$303,1)) | E24: =IF(OR($A24="",N(D24)=0),"",C24/D24) | F24: =IF(OR($A24="",N(D24)=0),"",IF(C24>=D24*$L$4,"✔ Yes","✘ No")) | G24: =IF($A24="","",COUNTIFS($AC$7:$AC$303,$A24,$AH$7:$AH$303,1,$AL$7:$AL$303,1)) | H24: =IF($A24="","",COUNTIFS($AC$7:$AC$303,$A24,$AI$7:$AI$303,1,$AL$7:$AL$303,1)) | I24: =IF($A24="","",H24&" of "&G24) | J24: =IF($A24="","",COUNTIFS($AC$7:$AC$303,$A24,$AJ$7:$AJ$303,1,$AL$7:$AL$303,1)) | K24: =IF($A24="","",SUMIFS($AE$7:$AE$303,$AC$7:$AC$303,$A24,$AJ$7:$AJ$303,1,$AL$7:$AL$303,1)) | L24: =IF($A24="","",SUMIFS($AG$7:$AG$303,$AC$7:$AC$303,$A24,$AJ$7:$AJ$303,1,$AL$7:$AL$303,1)) | M24: =IF(OR($A24="",N(L24)=0),"",K24/L24-1) | N24: =IF(OR($A24="",N(L24)=0),"",IF(K24>=L24*$O$4,"✔ Yes","✘ No")) | O24: =IF($A24="","",COUNTIFS($AC$7:$AC$303,$A24,$AK$7:$AK$303,1,$AL$7:$AL$303,1)) | P24: =IF($A24="","",O24&" of "&J24) | Q24: =IF($A24="","",SUMIFS($AM$7:$AM$303,$AC$7:$AC$303,$A24,$AL$7:$AL$303,1)) | R24: =IF(OR($A24="",N(Q24)=0),"",C24/Q24-1) | S24: =IF($A24="","",IFERROR(Q24/SUMIFS($AN$7:$AN$303,$AC$7:$AC$303,$A24,$AL$7:$AL$303,1),"")) | T24: =IF(OR(E24="",S24=""),"",(E24-S24)*100) | U24: =IF(S24="","",IF(S24>=$L$4,"✔ Yes","✘ No")) | V24: =IF($A24="","",COUNTIFS($AC$7:$AC$303,$A24,$AQ$7:$AQ$303,1,$AL$7:$AL$303,1)&" of "&COUNTIFS($AC$7:$AC$303,$A24,$AP$7:$AP$303,1,$AL$7:$AL$303,1)) | W24: =IF($A24="","",IFERROR(SUMIFS($AM$7:$AM$303,$AC$7:$AC$303,$A24,$AR$7:$AR$303,1,$AL$7:$AL$303,1)/SUMIFS($AO$7:$AO$303,$AC$7:$AC$303,$A24,$AR$7:$AR$303,1,$AL$7:$AL$303,1)-1,"")) | X24: =IF($A24="","",COUNTIFS($AC$7:$AC$303,$A24,$AS$7:$AS$303,1,$AL$7:$AL$303,1)&" of "&COUNTIFS($AC$7:$AC$303,$A24,$AR$7:$AR$303,1,$AL$7:$AL$303,1)) | AB24: =IF('Sales Dashboard'!AW23="","",'Sales Dashboard'!AW23) -> ALBUSTAN | AC24: =IF(AB24="","",'Sales Dashboard'!AN23) -> Hamzah Al Makhadam | AD24: =IF(AB24="","",'Sales Dashboard'!AO23) -> Al Hasa | AE24: {=IF(OR(AB24="",NOT(ISNUMBER('Sales Dashboard'!BF23))),0,SUMPRODUCT((IFERROR(--'Sales and count'!$G$2:$CC$2,0)=$C$4)*('Sales and count'!$G$3:$CC$3="Total"),INDEX('Sales and count'!$G$4:$CC$300,'Sales Dashboard'!BF23,0)))} -> 14865.32 | AF24: {=IF(OR(AB24="",NOT(ISNUMBER('Sales Dashboard'!BG23))),0,SUMPRODUCT(('TY Sales Target'!$K$2:$AO$2=$C$4)*1,INDEX('TY Sales Target'!$K$5:$AO$300,'Sales Dashboard'!BG23,0)))} -> 19250.678 | AG24: {=IF(AB24="",0,SUMPRODUCT((TRIM('LY Sales '!$B$5:$B$200)=AB24)*('LY Sales '!$C$2:$AG$2=EDATE($C$4,-12)),'LY Sales '!$C$5:$AG$200))} -> 20857.7 | AH24: =--AND(AB24<>"",AF24>0) -> 1 | AI24: =--AND(AH24=1,AE24>=AF24*$L$4) -> 0 | AJ24: =--AND(AB24<>"",AG24>0) -> 1 | AK24: =--AND(AJ24=1,AE24>=AG24*$O$4) -> 0 | AL24: =--AND(AC24<>"",AC24<>"No assignment",AC24<>"Unassigned") -> 1 | AM24: {=IF(OR(AB24="",NOT(ISNUMBER('Sales Dashboard'!BF23))),0,SUMPRODUCT((IFERROR(--'Sales and count'!$G$2:$CC$2,0)=$F$4)*('Sales and count'!$G$3:$CC$3="Total"),INDEX('Sales and count'!$G$4:$CC$300,'Sales Dashboard'!BF23,0)))} -> 4586.31 | AN24: {=IF(OR(AB24="",NOT(ISNUMBER('Sales Dashboard'!BG23))),0,SUMPRODUCT(('TY Sales Target'!$K$2:$AO$2=$F$4)*1,INDEX('TY Sales Target'!$K$5:$AO$300,'Sales Dashboard'!BG23,0)))} -> 13365.983 | AO24: {=IF(AB24="",0,SUMPRODUCT((TRIM('LY Sales '!$B$5:$B$200)=AB24)*('LY Sales '!$C$2:$AG$2=EDATE($F$4,-12)),'LY Sales '!$C$5:$AG$200))} -> 8321.19 | AP24: =--AND(AB24<>"",AN24>0) -> 1 | AQ24: =--AND(AP24=1,AM24>=AN24*$L$4) -> 0 | AR24: =--AND(AB24<>"",AO24>0) -> 1 | AS24: =--AND(AR24=1,AM24>=AO24*$O$4) -> 0 | AU24: 46314
